Workbook

Sheet Start Here
B5: Pathway-Mapping Tool (draft prototype)
B6: Map industry competencies to education, assign partner roles, find duplication and gaps, and open multiple entry points into technician careers.
B8: The five steps
B9: Step | C9: What you do | D9: Worksheet | E9: How
B10: 1 | C10: Define the roles | D10: 1 Roles | E10: Name the role families employers hire for, with O*NET/CIP codes and day-one, year-one, year-three tasks.
B11: 2 | C11: Map competencies to education | D11: 2 Competency Spine | E11: One row per competency. Set the depth each role needs (Core / Working / Aware) and where each is taught: high school, community college, university, industry credential, non-credit or apprenticeship.
B12: 3 | C12: Assign partner roles | D12: 3 Partner Roles | E12: Mark who Leads (L) and who Supports (S) each function. The sheet flags functions with no lead or more than one.
B13: 4 | C13: Find overlaps and gaps | D13: 4 Overlap and Gaps | E13: Flags are calculated from the spine. For each “Check” row, answer the three questions: same audience, same depth, same credential?
B14: 5 | C14: Open multiple entry points | D14: 5 Entry Points | E14: List the stops (credentials with job value) and the doors onto them, with how credit connects.
B16: Then check the Summary sheet for counts of gaps, overlaps, and partner functions without a lead.
B18: How to read the colors
C19: Your input
C20: Calculated from other sheets; don’t type here
B22: Adapting the tool to another sector
B23: 1. | C23: Rename the five role families on “1 Roles”; the spine and summary column headers update automatically.
B24: 2. | C24: Replace the rows on “2 Competency Spine” with your sector’s competencies (keep the column layout). Relabel the “where taught” columns if your layers differ.
B25: 3. | C25: Keep course codes in one cell per layer, separated by “ / ” (for example, ABC101 / ABC205). The overlap check counts them.
B26: 4. | C26: Overwrite the Arizona example entries on sheets 3 and 5 with your own partners and doors.
B28: Source of the starter competency spine
B29: Seeded from the SciTech Institute Semiconductor Manufacturing Skills Crosswalk (full copy on the “Source Crosswalk” sheet): 6 core, 11 cluster, and 73 pathway competencies across five O*NET role families. Core rows combine the source’s multi-row entries; course codes and standards are carried over as written.
B31: SP-ATE: Semiconductor Pathways in Arizona’s Technical Education, Rio Salado College. This material is based upon work supported by the National Science Foundation under Grant #2500695. Any opinions, findings, and conclusions or recommendations expressed in this material are those of the author(s) and do not necessarily reflect the views of the National Science Foundation. This project is funded by the Advanced Technological Education program and is supported in part by funds from Intel Corporation under the ETSTE DCL.
B32: Contact: Rick Vaughn, Ph.D., Rick.Vaughn@riosalado.edu

Sheet 1 Roles
A1: Step 1 · Define the roles
A2: Start from the jobs employers hire for, not from programs. Build each profile from employer job descriptions, high-level certification domains, and industry advisory input.
A3: Legend: cream cells = your input · gray cells = calculated (don’t edit) · “Example” rows show the Arizona worked example; overwrite them.
A5: ID | B5: Role family (rename to fit your sector) | C5: O*NET code | D5: CIP code | E5: Example job titles | F5: Day one: what they do | G5: Year one | H5: Year three | I5: Employer job descriptions reviewed? | J5: Certification domains used? | K5: Advisory board reviewed? | L5: # Core competencies (from spine) | M5: Notes
A6: R1 | B6: Automation, Controls & Sensor Technologies | C6: 17-3023.00 | D6: 47.0105 | L6: =COUNTIF('2 Competency Spine'!H$6:H$300,"Core") -> 18
A7: R2 | B7: Data, Cybersecurity & Infrastructure | C7: 15-1231.00 | D7: 11.1003 | L7: =COUNTIF('2 Competency Spine'!I$6:I$300,"Core") -> 14
A8: R3 | B8: Equipment & Systems Maintenance | C8: 49-9071.00 | D8: 46.0401 | E8: Example: equipment technician | F8: Example: cleanroom gowning, lockout/tagout, run diagnostics software | G8: Example: service pneumatic and hydraulic systems; chamber seal leak detection | H8: Example: vacuum pump overhaul; plasma etch system repair | L8: =COUNTIF('2 Competency Spine'!J$6:J$300,"Core") -> 13 | M8: Example tasks drawn from this pathway’s crosswalk competencies; confirm with employers.
A9: R4 | B9: Manufacturing Operations | C9: 51-9141.00 | D9: 15.0616 | L9: =COUNTIF('2 Competency Spine'!K$6:K$300,"Core") -> 13
A10: R5 | B10: Process Engineering & Quality | C10: 17-2199.00 | D10: 14.3601 | L10: =COUNTIF('2 Competency Spine'!L$6:L$300,"Core") -> 15

Sheet 2 Competency Spine
A1: Step 2 · Map competencies to education
A2: One competency spine for every offering. Set the depth each role needs, then record where each competency is taught in each layer of the system.
A3: Legend: cream cells = your input · gray cells = calculated (don’t edit) · “Example” rows show the Arizona worked example; overwrite them.
A4: Competency | H4: Depth each role needs (Core / Working / Aware) | M4: Where it’s taught | S4: Check
A5: ID | B5: Tier | C5: Competency | D5: Skill category | E5: Pathway (role family) | F5: O*NET | G5: CIP | H5: ='1 Roles'!B6 -> Automation, Controls & Sensor Technologies | I5: ='1 Roles'!B7 -> Data, Cybersecurity & Infrastructure | J5: ='1 Roles'!B8 -> Equipment & Systems Maintenance | K5: ='1 Roles'!B9 -> Manufacturing Operations | L5: ='1 Roles'!B10 -> Process Engineering & Quality | M5: High school: ADE standards | N5: High school: PLTW | O5: Community college: MCCCD | P5: University: UA | Q5: Industry credential: Chip Path | R5: Non-credit / apprenticeship | S5: # layers teaching it | T5: Notes
A6: C-01 | B6: Core | C6: Communication | D6: Core employability | E6: All pathways | M6: 7.13; 1.7; 7.5; 7.2; 11.2; 1.8 | N6: PLTW Engineering (EDD, IED); PLTW Biomedical Science (BI); PLTW Gateway (DM) | O6: MNT140 | P6: CHEE 415 / SIE 465 | Q6: CP-101 | S6: =IF(OR(M6<>"",N6<>""),1,0)+IF(O6<>"",1,0)+IF(P6<>"",1,0)+IF(Q6<>"",1,0)+IF(R6<>"",1,0) -> 4
A7: C-02 | B7: Core | C7: Collaboration | D7: Core employability | E7: All pathways | M7: 2.8 | N7: PLTW Engineering (POE, CIM); PLTW Computer Science (SEC); PLTW Gateway (AR) | O7: MNT140 | P7: MSE/ECE 447/ SIE 483 | Q7: CP-102 | S7: =IF(OR(M7<>"",N7<>""),1,0)+IF(O7<>"",1,0)+IF(P7<>"",1,0)+IF(Q7<>"",1,0)+IF(R7<>"",1,0) -> 4
A8: C-03 | B8: Core | C8: Digital Fluency | D8: Core employability | E8: All pathways | M8: 7.12; 11.1 | N8: PLTW Engineering (IED, DE, CIM); PLTW Computer Science (CSE, CSA, SEC); PLTW Gateway (AC) | O8: AIT132 | P8: ECE 407/SIE 483/MSE 480 | Q8: CP-103 | S8: =IF(OR(M8<>"",N8<>""),1,0)+IF(O8<>"",1,0)+IF(P8<>"",1,0)+IF(Q8<>"",1,0)+IF(R8<>"",1,0) -> 4
A9: C-04 | B9: Core | C9: Critical Thinking & Problem Solving | D9: Core employability | E9: All pathways | M9: 7.1; 8.3; 5.12; 2.5; 9.5/9.6 | N9: PLTW Engineering (IED, POE, EDD); PLTW Biomedical Science (PBS, MI); PLTW Gateway (MD) | O9: AIT132 | P9: MSE/ECE 447/547 | Q9: CP-104 | S9: =IF(OR(M9<>"",N9<>""),1,0)+IF(O9<>"",1,0)+IF(P9<>"",1,0)+IF(Q9<>"",1,0)+IF(R9<>"",1,0) -> 4
A10: C-05 | B10: Core | C10: Numeracy | D10: Core employability | E10: All pathways | M10: 7.4 | N10: PLTW Engineering (POE, DE, IED); PLTW Biomedical Science (HBS, MI); PLTW Computer Science (CSA) | O10: MNT235 | P10: SIE 305/SIE 430 | Q10: CP-105 | S10: =IF(OR(M10<>"",N10<>""),1,0)+IF(O10<>"",1,0)+IF(P10<>"",1,0)+IF(Q10<>"",1,0)+IF(R10<>"",1,0) -> 4
A11: C-06 | B11: Core | C11: Reading & Writing | D11: Core employability | E11: All pathways | M11: 11.6/11.7; 2.8 | N11: PLTW Engineering (All, esp. EDD, IED); PLTW Biomedical Science (PBS, BI); PLTW Computer Science (SEC) | O11: ENG101 | P11: CHEE 415 | Q11: CP-106 | S11: =IF(OR(M11<>"",N11<>""),1,0)+IF(O11<>"",1,0)+IF(P11<>"",1,0)+IF(Q11<>"",1,0)+IF(R11<>"",1,0) -> 4
A12: K-01 | B12: Cluster | C12: Interpret basic electrical & circuit concepts & diagrams | D12: Technical Foundations | E12: All pathways | M12: 6.1-6.4; 7.2 | N12: PLTW Engineering (DE, POE) | O12: AIT132 | P12: ECE 220 | Q12: CP-101 / ELC-101 | S12: =IF(OR(M12<>"",N12<>""),1,0)+IF(O12<>"",1,0)+IF(P12<>"",1,0)+IF(Q12<>"",1,0)+IF(R12<>"",1,0) -> 4
A13: K-02 | B13: Cluster | C13: Use AI and ML tools to optimize manufacturing | D13: Data, Analysis, & Digital Tools | E13: All pathways | M13: 7.9 | N13: PLTW Computer Science (CSE, CSA) | O13: AIM230 | P13: SIE 574 | Q13: CP-103 / DAT-110 | S13: =IF(OR(M13<>"",N13<>""),1,0)+IF(O13<>"",1,0)+IF(P13<>"",1,0)+IF(Q13<>"",1,0)+IF(R13<>"",1,0) -> 4
A14: K-03 | B14: Cluster | C14: Use SPC charts and data tools to monitor processes | D14: Data, Analysis, & Digital Tools | E14: All pathways | M14: 7.1; 9.7 | N14: PLTW Engineering (IED, CIM) | O14: MNT108 | P14: SIE 540 | Q14: CP-103 / GTC-108 | S14: =IF(OR(M14<>"",N14<>""),1,0)+IF(O14<>"",1,0)+IF(P14<>"",1,0)+IF(Q14<>"",1,0)+IF(R14<>"",1,0) -> 4
A15: K-04 | B15: Cluster | C15: Recognize & respond to physical security & cybersecurity risks | D15: Safety, Security & Compliance | E15: All pathways | M15: Standard 11.0 | N15: PLTW Computer Science (SEC) | O15: CIS270 / ITS110 | P15: ECE 578 | Q15: CP-101 / CIS-110 | S15: =IF(OR(M15<>"",N15<>""),1,0)+IF(O15<>"",1,0)+IF(P15<>"",1,0)+IF(Q15<>"",1,0)+IF(R15<>"",1,0) -> 4
A16: K-05 | B16: Cluster | C16: Follow OSHA, COHE, & cleanroom safety protocols | D16: Safety, Security & Compliance | E16: All pathways | M16: 2.1; 2.8 | N16: PLTW Engineering (CIM, POE) | O16: MNT201 | P16: MSE / ECE / CHEE 515: | Q16: CP-101 / AIT-101 | S16: =IF(OR(M16<>"",N16<>""),1,0)+IF(O16<>"",1,0)+IF(P16<>"",1,0)+IF(Q16<>"",1,0)+IF(R16<>"",1,0) -> 4
A17: K-06 | B17: Cluster | C17: Diagnose issues in semiconductor tools & systems | D17: Equipment, Systems & Automation | E17: All pathways | M17: 5.12; 6.8-6.10 | N17: PLTW Engineering (POE, DE, CIM) | O17: AIT132 | P17: MSE / ECE 547L: | Q17: CP-104 / AIT-215 | S17: =IF(OR(M17<>"",N17<>""),1,0)+IF(O17<>"",1,0)+IF(P17<>"",1,0)+IF(Q17<>"",1,0)+IF(R17<>"",1,0) -> 4
... A22: K-11 | B22: Cluster | C22: Maintain cleanroom gowning & housekeeping | D22: Cross-Cutting | E22: All pathways | M22: 2.8 | N22: PLTW Biomedical Science (PBS, MI) | O22: MNT201 | P22: FASTLab Training: Cleanroom Operations & Protocols | Q22: CP-101 / AIT-101 | S22: =IF(OR(M22<>"",N22<>""),1,0)+IF(O22<>"",1,0)+IF(P22<>"",1,0)+IF(Q22<>"",1,0)+IF(R22<>"",1,0) -> 4
A23: AUT-01 | B23: Pathway | C23: Apply control systems concepts | E23: Automation, Controls & Sensor Technologies | F23: 17-3023.00 | G23: 47.0105 | H23: Core | M23: Standard 8.0; Standard 10.0 | O23: AIT215 | P23: ECE 441A / AME 455 | Q23: CP-102 / AIT-125 | S23: =IF(OR(M23<>"",N23<>""),1,0)+IF(O23<>"",1,0)+IF(P23<>"",1,0)+IF(Q23<>"",1,0)+IF(R23<>"",1,0) -> 4
A24: AUT-02 | B24: Pathway | C24: Interpret PLC & sensor logic | E24: Automation, Controls & Sensor Technologies | F24: 17-3023.00 | G24: 47.0105 | H24: Core | M24: 10.1-10.5; Standard 8.0 | O24: AIT210 | P24: CYBV 330 | Q24: CP-102 / AIT-125 | S24: =IF(OR(M24<>"",N24<>""),1,0)+IF(O24<>"",1,0)+IF(P24<>"",1,0)+IF(Q24<>"",1,0)+IF(R24<>"",1,0) -> 4
A25: AUT-03 | B25: Pathway | C25: Apply basic scripting for automation tasks | E25: Automation, Controls & Sensor Technologies | F25: 17-3023.00 | G25: 47.0105 | H25: Core | M25: 7.12 | O25: CIS156 | P25: ECE 101 / ECE 201 | Q25: CP-103 / DAT-110 | S25: =IF(OR(M25<>"",N25<>""),1,0)+IF(O25<>"",1,0)+IF(P25<>"",1,0)+IF(Q25<>"",1,0)+IF(R25<>"",1,0) -> 4
A26: AUT-04 | B26: Pathway | C26: Validate failsafe shutdown behaviors | E26: Automation, Controls & Sensor Technologies | F26: 17-3023.00 | G26: 47.0105 | H26: Core | M26: 2.6 | O26: AIT100 | P26: CYBV 330 / AME 463 | Q26: CP-101 / AIT-101 | S26: =IF(OR(M26<>"",N26<>""),1,0)+IF(O26<>"",1,0)+IF(P26<>"",1,0)+IF(Q26<>"",1,0)+IF(R26<>"",1,0) -> 4
A27: AUT-05 | B27: Pathway | C27: Implement machine safeguarding & interlocks | E27: Automation, Controls & Sensor Technologies | F27: 17-3023.00 | G27: 47.0105 | H27: Core | M27: 2.2; 2.5 | O27: AIT100 | P27: MNE 426 / CYBV 330 | Q27: CP-101 / AIT-101 | S27: =IF(OR(M27<>"",N27<>""),1,0)+IF(O27<>"",1,0)+IF(P27<>"",1,0)+IF(Q27<>"",1,0)+IF(R27<>"",1,0) -> 4
A28: AUT-06 | B28: Pathway | C28: Integrate robots | E28: Automation, Controls & Sensor Technologies | F28: 17-3023.00 | G28: 47.0105 | H28: Core | M28: 7.11 | O28: AIT270 | P28: AME 551 | Q28: CP-102 / AIT-220 | S28: =IF(OR(M28<>"",N28<>""),1,0)+IF(O28<>"",1,0)+IF(P28<>"",1,0)+IF(Q28<>"",1,0)+IF(R28<>"",1,0) -> 4
A29: AUT-07 | B29: Pathway | C29: Configure PLC I/O modules | E29: Automation, Controls & Sensor Technologies | F29: 17-3023.00 | G29: 47.0105 | H29: Core | M29: 10.2; 10.5 | O29: AIT210 | P29: CYBV 330 / ECE 372A | Q29: CP-102 / AIT-125 | S29: =IF(OR(M29<>"",N29<>""),1,0)+IF(O29<>"",1,0)+IF(P29<>"",1,0)+IF(Q29<>"",1,0)+IF(R29<>"",1,0) -> 4
A30: AUT-08 | B30: Pathway | C30: Validate sensor-based control performance | E30: Automation, Controls & Sensor Technologies | F30: 17-3023.00 | G30: 47.0105 | H30: Core | M30: 8.6-8.7 | O30: AIT215 | P30: ECE 442 | Q30: CP-102 / AIT-125 | S30: =IF(OR(M30<>"",N30<>""),1,0)+IF(O30<>"",1,0)+IF(P30<>"",1,0)+IF(Q30<>"",1,0)+IF(R30<>"",1,0) -> 4
A31: AUT-09 | B31: Pathway | C31: Control loop theory | D31: Technical Foundations | E31: Automation, Controls & Sensor Technologies | F31: 17-3023.00 | G31: 47.0105 | H31: Core | O31: ELC210 / MET220 | P31: ECE 441A | Q31: CP-102 / AIT-125 | S31: =IF(OR(M31<>"",N31<>""),1,0)+IF(O31<>"",1,0)+IF(P31<>"",1,0)+IF(Q31<>"",1,0)+IF(R31<>"",1,0) -> 3
A32: AUT-10 | B32: Pathway | C32: Sensor calibration principles | D32: Technical Foundations | E32: Automation, Controls & Sensor Technologies | F32: 17-3023.00 | G32: 47.0105 | H32: Core | O32: ELC210 / MET220 | P32: MSE / ECE 547L | Q32: CP-104 / MET-210 | S32: =IF(OR(M32<>"",N32<>""),1,0)+IF(O32<>"",1,0)+IF(P32<>"",1,0)+IF(Q32<>"",1,0)+IF(R32<>"",1,0) -> 3
A33: AUT-11 | B33: Pathway | C33: SCADA alarm analytics | D33: Data, Analysis, & Digital Tools | E33: Automation, Controls & Sensor Technologies | F33: 17-3023.00 | G33: 47.0105 | H33: Core | O33: ELC210 / MET220 | P33: CYBV 330 / SIE 506 | Q33: CP-103 / DAT-110 | S33: =IF(OR(M33<>"",N33<>""),1,0)+IF(O33<>"",1,0)+IF(P33<>"",1,0)+IF(Q33<>"",1,0)+IF(R33<>"",1,0) -> 3
A34: AUT-12 | B34: Pathway | C34: HMI telemetry visualization | D34: Data, Analysis, & Digital Tools | E34: Automation, Controls & Sensor Technologies | F34: 17-3023.00 | G34: 47.0105 | H34: Core | O34: ELC210 / MET220 | P34: CYBV 330 / ECE 372A | Q34: CP-102 / AIT-125 | S34: =IF(OR(M34<>"",N34<>""),1,0)+IF(O34<>"",1,0)+IF(P34<>"",1,0)+IF(Q34<>"",1,0)+IF(R34<>"",1,0) -> 3
A35: AUT-13 | B35: Pathway | C35: ISO 13849 safety circuit validation | D35: Safety, Security & Compliance | E35: Automation, Controls & Sensor Technologies | F35: 17-3023.00 | G35: 47.0105 | H35: Core | O35: MET220 / ELC210 | P35: SIE 508 / CYBV 330 | Q35: CP-101 / AIT-101 | S35: =IF(OR(M35<>"",N35<>""),1,0)+IF(O35<>"",1,0)+IF(P35<>"",1,0)+IF(Q35<>"",1,0)+IF(R35<>"",1,0) -> 3
A36: AUT-14 | B36: Pathway | C36: Fail-safe interlock testing | D36: Safety, Security & Compliance | E36: Automation, Controls & Sensor Technologies | F36: 17-3023.00 | G36: 47.0105 | H36: Core | O36: MET220 / ELC210 | P36: CYBV 330 / SIE 508 | Q36: CP-101 / AIT-101 | S36: =IF(OR(M36<>"",N36<>""),1,0)+IF(O36<>"",1,0)+IF(P36<>"",1,0)+IF(Q36<>"",1,0)+IF(R36<>"",1,0) -> 3
A37: AUT-15 | B37: Pathway | C37: SCADA system programming | D37: Equipment, Systems & Automation | E37: Automation, Controls & Sensor Technologies | F37: 17-3023.00 | G37: 47.0105 | H37: Core | O37: ELC210 / MET220 | P37: CYBV 330 | Q37: CP-102 / AIT-125 | S37: =IF(OR(M37<>"",N37<>""),1,0)+IF(O37<>"",1,0)+IF(P37<>"",1,0)+IF(Q37<>"",1,0)+IF(R37<>"",1,0) -> 3
A38: AUT-16 | B38: Pathway | C38: Programmable logic controller integration | D38: Equipment, Systems & Automation | E38: Automation, Controls & Sensor Technologies | F38: 17-3023.00 | G38: 47.0105 | H38: Core | O38: ELC210 | P38: CYBV 330 | Q38: CP-102 / AIT-125 | S38: =IF(OR(M38<>"",N38<>""),1,0)+IF(O38<>"",1,0)+IF(P38<>"",1,0)+IF(Q38<>"",1,0)+IF(R38<>"",1,0) -> 3
A39: AUT-17 | B39: Pathway | C39: PLC program modification | D39: Manufacturing Processes & Quality | E39: Automation, Controls & Sensor Technologies | F39: 17-3023.00 | G39: 47.0105 | H39: Core | O39: ELC210 | P39: CYBV 330 | Q39: CP-102 / AIT-125 | S39: =IF(OR(M39<>"",N39<>""),1,0)+IF(O39<>"",1,0)+IF(P39<>"",1,0)+IF(Q39<>"",1,0)+IF(R39<>"",1,0) -> 3
A40: AUT-18 | B40: Pathway | C40: Sensor error diagnostics | D40: Manufacturing Processes & Quality | E40: Automation, Controls & Sensor Technologies | F40: 17-3023.00 | G40: 47.0105 | H40: Core | O40: ELC210 / MET220 | P40: ECE 372A / SIE 508 | Q40: CP-104 / AIT-215 | S40: =IF(OR(M40<>"",N40<>""),1,0)+IF(O40<>"",1,0)+IF(P40<>"",1,0)+IF(Q40<>"",1,0)+IF(R40<>"",1,0) -> 3
A41: DAT-01 | B41: Pathway | C41: Apply AAA & CIA frameworks | E41: Data, Cybersecurity & Infrastructure | F41: 15-1231.00 | G41: 11.1003 | I41: Core | M41: 11.2; 11.3 | O41: ITS110 | P41: ECE 509 / CYBV 301 | Q41: CP-101 / CIS-110 | S41: =IF(OR(M41<>"",N41<>""),1,0)+IF(O41<>"",1,0)+IF(P41<>"",1,0)+IF(Q41<>"",1,0)+IF(R41<>"",1,0) -> 4
A42: DAT-02 | B42: Pathway | C42: Configure access controls on systems | E42: Data, Cybersecurity & Infrastructure | F42: 15-1231.00 | G42: 11.1003 | I42: Core | M42: 11.2 | O42: ITS120 | P42: ECE 524 / CYBV 326 | Q42: CP-101 / CIS-110 | S42: =IF(OR(M42<>"",N42<>""),1,0)+IF(O42<>"",1,0)+IF(P42<>"",1,0)+IF(Q42<>"",1,0)+IF(R42<>"",1,0) -> 4
A43: DAT-03 | B43: Pathway | C43: Support quality audits | E43: Data, Cybersecurity & Infrastructure | F43: 15-1231.00 | G43: 11.1003 | I43: Core | M43: 9.8 | O43: MNT235 | P43: SIE 567 / SIE 530 | Q43: CP-103 / MET-210 | S43: =IF(OR(M43<>"",N43<>""),1,0)+IF(O43<>"",1,0)+IF(P43<>"",1,0)+IF(Q43<>"",1,0)+IF(R43<>"",1,0) -> 4
A44: DAT-04 | B44: Pathway | C44: Monitor data integrity | E44: Data, Cybersecurity & Infrastructure | F44: 15-1231.00 | G44: 11.1003 | I44: Core | M44: 11.3 | O44: MNT108 | P44: SFWE 501 / ECE 519 | Q44: CP-103 / DAT-110 | S44: =IF(OR(M44<>"",N44<>""),1,0)+IF(O44<>"",1,0)+IF(P44<>"",1,0)+IF(Q44<>"",1,0)+IF(R44<>"",1,0) -> 4
...

Sheet 3 Partner Roles
A1: Step 3 · Assign partner roles
A2: Give every partner a clear lane: one Lead (L) per function, everyone else Supports (S). Rename the partner columns to fit your region.
A3: Legend: cream cells = your input · gray cells = calculated (don’t edit) · “Example” rows show the Arizona worked example; overwrite them.
A5: Function | B5: Description | C5: High schools | D5: Community colleges | E5: Universities | F5: Employers | G5: Certification bodies | H5: State & regional | I5: [Add partner] | J5: # leads | K5: Status
A6: Organizations in your region | B6: Who fills each column | C6: Example: Chandler Unified School District | D6: Example: Rio Salado College, Maricopa district | E6: Example: NAU, ASU, University of Arizona | F6: Example: TSMC and advisory employers | G6: Example: SEMI Foundation, NOCTI | H6: Example: Arizona Commerce Authority
A7: Career exposure | B7: Tours, industry speakers, career awareness for students, parents, counselors | C7: L | D7: S | E7: S | F7: S | H7: S | J7: =COUNTIF(C7:I7,"L") -> 1 | K7: =IF(A7="","",IF(J7=0,"No lead",IF(J7>1,"Multiple leads: clarify","OK"))) -> OK
A8: Dual enrollment | B8: College credit in high school, using the same industry-endorsed certificate | C8: L | D8: L | J8: =COUNTIF(C8:I8,"L") -> 2 | K8: =IF(A8="","",IF(J8=0,"No lead",IF(J8>1,"Multiple leads: clarify","OK"))) -> Multiple leads: clarify
A9: Stackable credentials | B9: Certificates that stack into a degree, each with job value | D9: L | F9: S | G9: S | J9: =COUNTIF(C9:I9,"L") -> 1 | K9: =IF(A9="","",IF(J9=0,"No lead",IF(J9>1,"Multiple leads: clarify","OK"))) -> OK
A10: Core technician training | B10: Credit and non-credit technical instruction | D10: L | F10: S | J10: =COUNTIF(C10:I10,"L") -> 1 | K10: =IF(A10="","",IF(J10=0,"No lead",IF(J10>1,"Multiple leads: clarify","OK"))) -> OK
A11: Hands-on lab access | B11: Cleanroom and tool time beyond college labs | D11: S | E11: L | F11: S | J11: =COUNTIF(C11:I11,"L") -> 1 | K11: =IF(A11="","",IF(J11=0,"No lead",IF(J11>1,"Multiple leads: clarify","OK"))) -> OK
A12: Articulation and transfer | B12: Credit transfer to bachelor’s completion | D12: S | E12: L | J12: =COUNTIF(C12:I12,"L") -> 1 | K12: =IF(A12="","",IF(J12=0,"No lead",IF(J12>1,"Multiple leads: clarify","OK"))) -> OK
A13: Job descriptions and advisory input | B13: Defines roles and competencies; reviews the map | D13: S | F13: L | J13: =COUNTIF(C13:I13,"L") -> 1 | K13: =IF(A13="","",IF(J13=0,"No lead",IF(J13>1,"Multiple leads: clarify","OK"))) -> OK
A14: Apprenticeships | B14: On-the-job learning with related technical instruction | D14: S | F14: L | G14: S | J14: =COUNTIF(C14:I14,"L") -> 1 | K14: =IF(A14="","",IF(J14=0,"No lead",IF(J14>1,"Multiple leads: clarify","OK"))) -> OK
A15: Industry certification | B15: Third-party validation of competencies | D15: S | F15: S | G15: L | J15: =COUNTIF(C15:I15,"L") -> 1 | K15: =IF(A15="","",IF(J15=0,"No lead",IF(J15>1,"Multiple leads: clarify","OK"))) -> OK
A16: Investment and convening | B16: Statewide funding, coordination, regional planning | D16: S | F16: S | H16: L | J16: =COUNTIF(C16:I16,"L") -> 1 | K16: =IF(A16="","",IF(J16=0,"No lead",IF(J16>1,"Multiple leads: clarify","OK"))) -> OK
J17: =COUNTIF(C17:I17,"L") -> 0 | K17: =IF(A17="","",IF(J17=0,"No lead",IF(J17>1,"Multiple leads: clarify","OK")))
J18: =COUNTIF(C18:I18,"L") -> 0 | K18: =IF(A18="","",IF(J18=0,"No lead",IF(J18>1,"Multiple leads: clarify","OK")))
J19: =COUNTIF(C19:I19,"L") -> 0 | K19: =IF(A19="","",IF(J19=0,"No lead",IF(J19>1,"Multiple leads: clarify","OK")))
A21: Example marks show the Arizona worked example. Dual enrollment intentionally has two leads (high school and college) to show the flag; decide whether shared leadership works for you.

Sheet 4 Overlap and Gaps
A1: Step 4 · Find overlaps and gaps
A2: Calculated from the spine. Gaps need an owner. For each “Check” row, answer the three questions: three Yes answers mean duplication to coordinate; otherwise it may be a healthy on-ramp.
A3: Legend: cream cells = your input · gray cells = calculated (don’t edit) · “Example” rows show the Arizona worked example; overwrite them.
A5: ID | B5: Competency | C5: Tier | D5: Pathway | E5: Community college offering(s) | F5: # CC courses | G5: High school on-ramp? | H5: # layers teaching it | I5: Status | J5: Same audience? | K5: Same depth? | L5: Same credential? | M5: Verdict | N5: Action (coordinate, build, borrow, keep) | O5: Owner
A6: =IF('2 Competency Spine'!A6="","",'2 Competency Spine'!A6) -> C-01 | B6: =IF('2 Competency Spine'!C6="","",'2 Competency Spine'!C6) -> Communication | C6: =IF('2 Competency Spine'!B6="","",'2 Competency Spine'!B6) -> Core | D6: =IF('2 Competency Spine'!E6="","",'2 Competency Spine'!E6) -> All pathways | E6: =IF('2 Competency Spine'!O6="","",'2 Competency Spine'!O6) -> MNT140 | F6: =IF(TRIM(E6)="",0,LEN(E6)-LEN(SUBSTITUTE(E6,"/",""))+1) -> 1 | G6: =IF(A6="","",IF(OR('2 Competency Spine'!M6<>"",'2 Competency Spine'!N6<>""),"Yes","No")) -> Yes | H6: ='2 Competency Spine'!S6 -> 4 | I6: =IF(A6="","",IF(H6=0,"Gap: not taught anywhere",IF(F6=0,"Gap: no community college offering",IF(F6>1,"Check: multiple CC courses",IF(G6="No","Covered: no high school on-ramp","Covered"))))) -> Covered | M6: =IF(LEFT(I6,5)<>"Check","",IF(COUNTIF(J6:L6,"Yes")+COUNTIF(J6:L6,"No")<3,"Answer the 3 questions",IF(COUNTIF(J6:L6,"Yes")=3,"Duplication: coordinate","Healthy on-ramp: keep")))
A7: =IF('2 Competency Spine'!A7="","",'2 Competency Spine'!A7) -> C-02 | B7: =IF('2 Competency Spine'!C7="","",'2 Competency Spine'!C7) -> Collaboration | C7: =IF('2 Competency Spine'!B7="","",'2 Competency Spine'!B7) -> Core | D7: =IF('2 Competency Spine'!E7="","",'2 Competency Spine'!E7) -> All pathways | E7: =IF('2 Competency Spine'!O7="","",'2 Competency Spine'!O7) -> MNT140 | F7: =IF(TRIM(E7)="",0,LEN(E7)-LEN(SUBSTITUTE(E7,"/",""))+1) -> 1 | G7: =IF(A7="","",IF(OR('2 Competency Spine'!M7<>"",'2 Competency Spine'!N7<>""),"Yes","No")) -> Yes | H7: ='2 Competency Spine'!S7 -> 4 | I7: =IF(A7="","",IF(H7=0,"Gap: not taught anywhere",IF(F7=0,"Gap: no community college offering",IF(F7>1,"Check: multiple CC courses",IF(G7="No","Covered: no high school on-ramp","Covered"))))) -> Covered | M7: =IF(LEFT(I7,5)<>"Check","",IF(COUNTIF(J7:L7,"Yes")+COUNTIF(J7:L7,"No")<3,"Answer the 3 questions",IF(COUNTIF(J7:L7,"Yes")=3,"Duplication: coordinate","Healthy on-ramp: keep")))
A8: =IF('2 Competency Spine'!A8="","",'2 Competency Spine'!A8) -> C-03 | B8: =IF('2 Competency Spine'!C8="","",'2 Competency Spine'!C8) -> Digital Fluency | C8: =IF('2 Competency Spine'!B8="","",'2 Competency Spine'!B8) -> Core | D8: =IF('2 Competency Spine'!E8="","",'2 Competency Spine'!E8) -> All pathways | E8: =IF('2 Competency Spine'!O8="","",'2 Competency Spine'!O8) -> AIT132 | F8: =IF(TRIM(E8)="",0,LEN(E8)-LEN(SUBSTITUTE(E8,"/",""))+1) -> 1 | G8: =IF(A8="","",IF(OR('2 Competency Spine'!M8<>"",'2 Competency Spine'!N8<>""),"Yes","No")) -> Yes | H8: ='2 Competency Spine'!S8 -> 4 | I8: =IF(A8="","",IF(H8=0,"Gap: not taught anywhere",IF(F8=0,"Gap: no community college offering",IF(F8>1,"Check: multiple CC courses",IF(G8="No","Covered: no high school on-ramp","Covered"))))) -> Covered | M8: =IF(LEFT(I8,5)<>"Check","",IF(COUNTIF(J8:L8,"Yes")+COUNTIF(J8:L8,"No")<3,"Answer the 3 questions",IF(COUNTIF(J8:L8,"Yes")=3,"Duplication: coordinate","Healthy on-ramp: keep")))
A9: =IF('2 Competency Spine'!A9="","",'2 Competency Spine'!A9) -> C-04 | B9: =IF('2 Competency Spine'!C9="","",'2 Competency Spine'!C9) -> Critical Thinking & Problem Solving | C9: =IF('2 Competency Spine'!B9="","",'2 Competency Spine'!B9) -> Core | D9: =IF('2 Competency Spine'!E9="","",'2 Competency Spine'!E9) -> All pathways | E9: =IF('2 Competency Spine'!O9="","",'2 Competency Spine'!O9) -> AIT132 | F9: =IF(TRIM(E9)="",0,LEN(E9)-LEN(SUBSTITUTE(E9,"/",""))+1) -> 1 | G9: =IF(A9="","",IF(OR('2 Competency Spine'!M9<>"",'2 Competency Spine'!N9<>""),"Yes","No")) -> Yes | H9: ='2 Competency Spine'!S9 -> 4 | I9: =IF(A9="","",IF(H9=0,"Gap: not taught anywhere",IF(F9=0,"Gap: no community college offering",IF(F9>1,"Check: multiple CC courses",IF(G9="No","Covered: no high school on-ramp","Covered"))))) -> Covered | M9: =IF(LEFT(I9,5)<>"Check","",IF(COUNTIF(J9:L9,"Yes")+COUNTIF(J9:L9,"No")<3,"Answer the 3 questions",IF(COUNTIF(J9:L9,"Yes")=3,"Duplication: coordinate","Healthy on-ramp: keep")))
A10: =IF('2 Competency Spine'!A10="","",'2 Competency Spine'!A10) -> C-05 | B10: =IF('2 Competency Spine'!C10="","",'2 Competency Spine'!C10) -> Numeracy | C10: =IF('2 Competency Spine'!B10="","",'2 Competency Spine'!B10) -> Core | D10: =IF('2 Competency Spine'!E10="","",'2 Competency Spine'!E10) -> All pathways | E10: =IF('2 Competency Spine'!O10="","",'2 Competency Spine'!O10) -> MNT235 | F10: =IF(TRIM(E10)="",0,LEN(E10)-LEN(SUBSTITUTE(E10,"/",""))+1) -> 1 | G10: =IF(A10="","",IF(OR('2 Competency Spine'!M10<>"",'2 Competency Spine'!N10<>""),"Yes","No")) -> Yes | H10: ='2 Competency Spine'!S10 -> 4 | I10: =IF(A10="","",IF(H10=0,"Gap: not taught anywhere",IF(F10=0,"Gap: no community college offering",IF(F10>1,"Check: multiple CC courses",IF(G10="No","Covered: no high school on-ramp","Covered"))))) -> Covered | M10: =IF(LEFT(I10,5)<>"Check","",IF(COUNTIF(J10:L10,"Yes")+COUNTIF(J10:L10,"No")<3,"Answer the 3 questions",IF(COUNTIF(J10:L10,"Yes")=3,"Duplication: coordinate","Healthy on-ramp: keep")))
A11: =IF('2 Competency Spine'!A11="","",'2 Competency Spine'!A11) -> C-06 | B11: =IF('2 Competency Spine'!C11="","",'2 Competency Spine'!C11) -> Reading & Writing | C11: =IF('2 Competency Spine'!B11="","",'2 Competency Spine'!B11) -> Core | D11: =IF('2 Competency Spine'!E11="","",'2 Competency Spine'!E11) -> All pathways | E11: =IF('2 Competency Spine'!O11="","",'2 Competency Spine'!O11) -> ENG101 | F11: =IF(TRIM(E11)="",0,LEN(E11)-LEN(SUBSTITUTE(E11,"/",""))+1) -> 1 | G11: =IF(A11="","",IF(OR('2 Competency Spine'!M11<>"",'2 Competency Spine'!N11<>""),"Yes","No")) -> Yes | H11: ='2 Competency Spine'!S11 -> 4 | I11: =IF(A11="","",IF(H11=0,"Gap: not taught anywhere",IF(F11=0,"Gap: no community college offering",IF(F11>1,"Check: multiple CC courses",IF(G11="No","Covered: no high school on-ramp","Covered"))))) -> Covered | M11: =IF(LEFT(I11,5)<>"Check","",IF(COUNTIF(J11:L11,"Yes")+COUNTIF(J11:L11,"No")<3,"Answer the 3 questions",IF(COUNTIF(J11:L11,"Yes")=3,"Duplication: coordinate","Healthy on-ramp: keep")))
A12: =IF('2 Competency Spine'!A12="","",'2 Competency Spine'!A12) -> K-01 | B12: =IF('2 Competency Spine'!C12="","",'2 Competency Spine'!C12) -> Interpret basic electrical & circuit concepts & diagrams | C12: =IF('2 Competency Spine'!B12="","",'2 Competency Spine'!B12) -> Cluster | D12: =IF('2 Competency Spine'!E12="","",'2 Competency Spine'!E12) -> All pathways | E12: =IF('2 Competency Spine'!O12="","",'2 Competency Spine'!O12) -> AIT132 | F12: =IF(TRIM(E12)="",0,LEN(E12)-LEN(SUBSTITUTE(E12,"/",""))+1) -> 1 | G12: =IF(A12="","",IF(OR('2 Competency Spine'!M12<>"",'2 Competency Spine'!N12<>""),"Yes","No")) -> Yes | H12: ='2 Competency Spine'!S12 -> 4 | I12: =IF(A12="","",IF(H12=0,"Gap: not taught anywhere",IF(F12=0,"Gap: no community college offering",IF(F12>1,"Check: multiple CC courses",IF(G12="No","Covered: no high school on-ramp","Covered"))))) -> Covered | M12: =IF(LEFT(I12,5)<>"Check","",IF(COUNTIF(J12:L12,"Yes")+COUNTIF(J12:L12,"No")<3,"Answer the 3 questions",IF(COUNTIF(J12:L12,"Yes")=3,"Duplication: coordinate","Healthy on-ramp: keep")))
A13: =IF('2 Competency Spine'!A13="","",'2 Competency Spine'!A13) -> K-02 | B13: =IF('2 Competency Spine'!C13="","",'2 Competency Spine'!C13) -> Use AI and ML tools to optimize manufacturing | C13: =IF('2 Competency Spine'!B13="","",'2 Competency Spine'!B13) -> Cluster | D13: =IF('2 Competency Spine'!E13="","",'2 Competency Spine'!E13) -> All pathways | E13: =IF('2 Competency Spine'!O13="","",'2 Competency Spine'!O13) -> AIM230 | F13: =IF(TRIM(E13)="",0,LEN(E13)-LEN(SUBSTITUTE(E13,"/",""))+1) -> 1 | G13: =IF(A13="","",IF(OR('2 Competency Spine'!M13<>"",'2 Competency Spine'!N13<>""),"Yes","No")) -> Yes | H13: ='2 Competency Spine'!S13 -> 4 | I13: =IF(A13="","",IF(H13=0,"Gap: not taught anywhere",IF(F13=0,"Gap: no community college offering",IF(F13>1,"Check: multiple CC courses",IF(G13="No","Covered: no high school on-ramp","Covered"))))) -> Covered | M13: =IF(LEFT(I13,5)<>"Check","",IF(COUNTIF(J13:L13,"Yes")+COUNTIF(J13:L13,"No")<3,"Answer the 3 questions",IF(COUNTIF(J13:L13,"Yes")=3,"Duplication: coordinate","Healthy on-ramp: keep")))
A14: =IF('2 Competency Spine'!A14="","",'2 Competency Spine'!A14) -> K-03 | B14: =IF('2 Competency Spine'!C14="","",'2 Competency Spine'!C14) -> Use SPC charts and data tools to monitor processes | C14: =IF('2 Competency Spine'!B14="","",'2 Competency Spine'!B14) -> Cluster | D14: =IF('2 Competency Spine'!E14="","",'2 Competency Spine'!E14) -> All pathways | E14: =IF('2 Competency Spine'!O14="","",'2 Competency Spine'!O14) -> MNT108 | F14: =IF(TRIM(E14)="",0,LEN(E14)-LEN(SUBSTITUTE(E14,"/",""))+1) -> 1 | G14: =IF(A14="","",IF(OR('2 Competency Spine'!M14<>"",'2 Competency Spine'!N14<>""),"Yes","No")) -> Yes | H14: ='2 Competency Spine'!S14 -> 4 | I14: =IF(A14="","",IF(H14=0,"Gap: not taught anywhere",IF(F14=0,"Gap: no community college offering",IF(F14>1,"Check: multiple CC courses",IF(G14="No","Covered: no high school on-ramp","Covered"))))) -> Covered | M14: =IF(LEFT(I14,5)<>"Check","",IF(COUNTIF(J14:L14,"Yes")+COUNTIF(J14:L14,"No")<3,"Answer the 3 questions",IF(COUNTIF(J14:L14,"Yes")=3,"Duplication: coordinate","Healthy on-ramp: keep")))
A15: =IF('2 Competency Spine'!A15="","",'2 Competency Spine'!A15) -> K-04 | B15: =IF('2 Competency Spine'!C15="","",'2 Competency Spine'!C15) -> Recognize & respond to physical security & cybersecurity risks | C15: =IF('2 Competency Spine'!B15="","",'2 Competency Spine'!B15) -> Cluster | D15: =IF('2 Competency Spine'!E15="","",'2 Competency Spine'!E15) -> All pathways | E15: =IF('2 Competency Spine'!O15="","",'2 Competency Spine'!O15) -> CIS270 / ITS110 | F15: =IF(TRIM(E15)="",0,LEN(E15)-LEN(SUBSTITUTE(E15,"/",""))+1) -> 2 | G15: =IF(A15="","",IF(OR('2 Competency Spine'!M15<>"",'2 Competency Spine'!N15<>""),"Yes","No")) -> Yes | H15: ='2 Competency Spine'!S15 -> 4 | I15: =IF(A15="","",IF(H15=0,"Gap: not taught anywhere",IF(F15=0,"Gap: no community college offering",IF(F15>1,"Check: multiple CC courses",IF(G15="No","Covered: no high school on-ramp","Covered"))))) -> Check: multiple CC courses | M15: =IF(LEFT(I15,5)<>"Check","",IF(COUNTIF(J15:L15,"Yes")+COUNTIF(J15:L15,"No")<3,"Answer the 3 questions",IF(COUNTIF(J15:L15,"Yes")=3,"Duplication: coordinate","Healthy on-ramp: keep"))) -> Answer the 3 questions
A16: =IF('2 Competency Spine'!A16="","",'2 Competency Spine'!A16) -> K-05 | B16: =IF('2 Competency Spine'!C16="","",'2 Competency Spine'!C16) -> Follow OSHA, COHE, & cleanroom safety protocols | C16: =IF('2 Competency Spine'!B16="","",'2 Competency Spine'!B16) -> Cluster | D16: =IF('2 Competency Spine'!E16="","",'2 Competency Spine'!E16) -> All pathways | E16: =IF('2 Competency Spine'!O16="","",'2 Competency Spine'!O16) -> MNT201 | F16: =IF(TRIM(E16)="",0,LEN(E16)-LEN(SUBSTITUTE(E16,"/",""))+1) -> 1 | G16: =IF(A16="","",IF(OR('2 Competency Spine'!M16<>"",'2 Competency Spine'!N16<>""),"Yes","No")) -> Yes | H16: ='2 Competency Spine'!S16 -> 4 | I16: =IF(A16="","",IF(H16=0,"Gap: not taught anywhere",IF(F16=0,"Gap: no community college offering",IF(F16>1,"Check: multiple CC courses",IF(G16="No","Covered: no high school on-ramp","Covered"))))) -> Covered | M16: =IF(LEFT(I16,5)<>"Check","",IF(COUNTIF(J16:L16,"Yes")+COUNTIF(J16:L16,"No")<3,"Answer the 3 questions",IF(COUNTIF(J16:L16,"Yes")=3,"Duplication: coordinate","Healthy on-ramp: keep")))
A17: =IF('2 Competency Spine'!A17="","",'2 Competency Spine'!A17) -> K-06 | B17: =IF('2 Competency Spine'!C17="","",'2 Competency Spine'!C17) -> Diagnose issues in semiconductor tools & systems | C17: =IF('2 Competency Spine'!B17="","",'2 Competency Spine'!B17) -> Cluster | D17: =IF('2 Competency Spine'!E17="","",'2 Competency Spine'!E17) -> All pathways | E17: =IF('2 Competency Spine'!O17="","",'2 Competency Spine'!O17) -> AIT132 | F17: =IF(TRIM(E17)="",0,LEN(E17)-LEN(SUBSTITUTE(E17,"/",""))+1) -> 1 | G17: =IF(A17="","",IF(OR('2 Competency Spine'!M17<>"",'2 Competency Spine'!N17<>""),"Yes","No")) -> Yes | H17: ='2 Competency Spine'!S17 -> 4 | I17: =IF(A17="","",IF(H17=0,"Gap: not taught anywhere",IF(F17=0,"Gap: no community college offering",IF(F17>1,"Check: multiple CC courses",IF(G17="No","Covered: no high school on-ramp","Covered"))))) -> Covered | M17: =IF(LEFT(I17,5)<>"Check","",IF(COUNTIF(J17:L17,"Yes")+COUNTIF(J17:L17,"No")<3,"Answer the 3 questions",IF(COUNTIF(J17:L17,"Yes")=3,"Duplication: coordinate","Healthy on-ramp: keep")))
... A95: =IF('2 Competency Spine'!A95="","",'2 Competency Spine'!A95) -> PEQ-15 | B95: =IF('2 Competency Spine'!C95="","",'2 Competency Spine'!C95) -> Design of experiments | C95: =IF('2 Competency Spine'!B95="","",'2 Competency Spine'!B95) -> Pathway | D95: =IF('2 Competency Spine'!E95="","",'2 Competency Spine'!E95) -> Process Engineering & Quality | E95: =IF('2 Competency Spine'!O95="","",'2 Competency Spine'!O95) -> GTC108 / SEM210 | F95: =IF(TRIM(E95)="",0,LEN(E95)-LEN(SUBSTITUTE(E95,"/",""))+1) -> 2 | G95: =IF(A95="","",IF(OR('2 Competency Spine'!M95<>"",'2 Competency Spine'!N95<>""),"Yes","No")) -> No | H95: ='2 Competency Spine'!S95 -> 3 | I95: =IF(A95="","",IF(H95=0,"Gap: not taught anywhere",IF(F95=0,"Gap: no community college offering",IF(F95>1,"Check: multiple CC courses",IF(G95="No","Covered: no high school on-ramp","Covered"))))) -> Check: multiple CC courses | M95: =IF(LEFT(I95,5)<>"Check","",IF(COUNTIF(J95:L95,"Yes")+COUNTIF(J95:L95,"No")<3,"Answer the 3 questions",IF(COUNTIF(J95:L95,"Yes")=3,"Duplication: coordinate","Healthy on-ramp: keep"))) -> Answer the 3 questions

Sheet 5 Entry Points
A1: Step 5 · Open multiple entry points
A2: Many doors onto one pathway. List the stops first (each with job value), then the doors and how credit connects so no learning is wasted.
A3: Legend: cream cells = your input · gray cells = calculated (don’t edit) · “Example” rows show the Arizona worked example; overwrite them.
A5: Stops on the pathway
A6: Stop | B6: Credential | C6: Job value: roles it qualifies for | D6: Competency IDs credited (from spine) | E6: Next stop | F6: Notes
A7: CCL-1 | B7: Entry certificate | E7: CCL-2
A8: CCL-2 | B8: Advanced certificate | E8: AAS
A9: AAS | B9: Associate degree | E9: Bachelor’s
A10: Bachelor’s | B10: Bachelor’s completion via NAU articulation
A15: Doors onto the pathway
A16: Door | B16: Who it serves | C16: Enters at (stop) | D16: Credit connection | E16: Offering(s) | F16: Lead partner | G16: Status | H16: Notes
A17: Example: High school students | B17: Dual enrollment students | C17: CCL-1 | D17: Dual enrollment | E17: Same industry-endorsed semiconductor manufacturing certificate | F17: High school + college
A18: Example: Adults new to the field | B18: Students starting from scratch | C18: CCL-1 | D18: Direct enrollment | E18: Entry certificate, beginning with the industry-overview course | F18: College
A19: Example: Apprentices | B19: Employer-sponsored apprentices | C19: CCL-1 | D19: Apprenticeship RTI crosswalk | E19: TSMC apprenticeship RTI crosswalk | F19: Employer + college
A20: Example: Working adults and career changers | B20: Incumbent workers; people with related experience | C20: CCL-1 | D20: Prior learning assessment | E20: Accelerated non-credit equipment training mapped to credit | F20: College
A21: Example: Transfer-bound students | B21: AAS graduates seeking a bachelor’s | C21: Bachelor’s | D21: Articulation | E21: NAU articulation | F21: University + college
A27: Every door should count toward the next stop, and every stop should lead to a job.

Sheet Summary
A1: Summary
A2: Updates as you fill in the other sheets.
A5: Competency spine
A6: Competencies on the spine | B6: =COUNTIF('2 Competency Spine'!B6:B155,"Core")+COUNTIF('2 Competency Spine'!B6:B155,"Cluster")+COUNTIF('2 Competency Spine'!B6:B155,"Pathway") -> 90
A7: Core | B7: =COUNTIF('2 Competency Spine'!B6:B155,"Core") -> 6
A8: Cluster | B8: =COUNTIF('2 Competency Spine'!B6:B155,"Cluster") -> 11
A9: Pathway | B9: =COUNTIF('2 Competency Spine'!B6:B155,"Pathway") -> 73
A11: Overlaps and gaps
A12: Gap: not taught anywhere | B12: =COUNTIF('4 Overlap and Gaps'!I6:I95,"Gap: not taught anywhere") -> 0
A13: Gap: no community college offering | B13: =COUNTIF('4 Overlap and Gaps'!I6:I95,"Gap: no community college offering") -> 0
A14: Check: multiple CC courses | B14: =COUNTIF('4 Overlap and Gaps'!I6:I95,"Check: multiple CC courses") -> 46
A15: of which, duplication to coordinate | B15: =COUNTIF('4 Overlap and Gaps'!M6:M95,"Duplication: coordinate") -> 0
A16: Covered: no high school on-ramp | B16: =COUNTIF('4 Overlap and Gaps'!I6:I95,"Covered: no high school on-ramp") -> 7
A17: Covered | B17: =COUNTIF('4 Overlap and Gaps'!I6:I95,"Covered") -> 37
A18: Taught in only one layer or none | B18: =COUNTIF('2 Competency Spine'!S6:S95,"<=1") -> 0
A20: Partners
A21: Functions with no lead | B21: =COUNTIF('3 Partner Roles'!K7:K19,"No lead") -> 0
A22: Functions with multiple leads | B22: =COUNTIF('3 Partner Roles'!K7:K19,"Multiple leads: clarify") -> 1
A24: Entry points
A25: Stops defined | B25: =COUNTA('5 Entry Points'!A7:A12) -> 4
A26: Doors defined | B26: =COUNTA('5 Entry Points'!A17:A25) -> 5
A27: Doors live | B27: =COUNTIF('5 Entry Points'!G17:G25,"Live") -> 0

Sheet Source Crosswalk
A1: Source: SciTech Institute Semiconductor Manufacturing Skills Crosswalk (copied as provided, for reference; edit the spine, not this sheet).
B3: Skill Category | C3: Domain | D3: O*Net Code | E3: CIP Code | F3: ADE Standard(s) | G3: Supporting ADE Standard Text | H3: MCCCD Course Code | I3: Supporting MCCCD Standard Text | J3: UA Course Code | K3: Supporting UA Standard Text | L3: Chip Path Courses | M3: Chip Path Supporting Text | N3: PLTW Courses | O3: Supporting PLTW Text | P3: 17-3023.00 (Electrical & Electronic Engineering Technologists & Techs) | Q3: 15-1231.00 (Computer Network Support Specialists) | R3: 49-9071.00 (Maintenance & Repair Workers, General) | S3: 17-2199.00 (Engineers, All Other / Mechatronics & Microsystems)
A4: CORE
A5: Communication | F5: 7.13 | G5: 7.13 Communicate technical information clearly using basic text and visual tools (e.g., PowerPoint presentations) | H5: MNT140 | I5: The program prepares students with the foundational expectations for interpersonal and professional skills within the industry. | J5: CHEE 415 / SIE 465 | K5: CHEE 415 connects semiconductor manufacturing processes with environmental implications, a context that requires communicating technical, regulatory, and operational considerations across disciplines. SIE 465 situates students in supply-chain decisions that typically require clear coordination among engineering, operations, suppliers, and customers. The co-curricular Fast Track explicitly includes an employer panel and final team presentations to industry partners, making it the clearest published communication-focused experience. | L5: CP-101 | M5: Articulates ideas clearly and effectively in written, verbal, and technical formats within multidisciplinary manufacturing environments. | N5: PLTW Engineering (EDD, IED) | O5: Students deliver oral technical presentations to panels of engineering professionals, generate standard CAD drawings, and present complex scientific concepts to non-technical stakeholders. | P5: Communicating with Supervisors, Peers, or Subordinates — Provide information to supervisors, co-workers, and subordinates by telephone, written form, email, or in person. | Q5: Answer user inquiries regarding computer software or hardware operation to resolve problems; explain resolution steps to technical and non-technical staff. | R5: Communicate with machine operators, tenants, or supervisors to discuss equipment performance, facility needs, and repair timelines. | S5: Present technical reports, design specifications, and operational recommendations to clients, engineering teams, and executive management.
F6: 1.7 | G6: 1.7 Summarize basic knowledge and skills needed by all levels of semiconductor workers (... cross-functional communication skills...) | N6: PLTW Biomedical Science (BI)
F7: 7.5 | G7: 7.5 (... explain yield in simple terms during a team discussion, etc.) | N7: PLTW Gateway (DM)
F8: 7.2 | G8: 7.2 Explain diagrams and basic technical drawings to understand equipment, processes, and systems (i.e., process flow diagrams, equipment schematics, simple system layouts, etc.)
F9: 11.2 | G9: 11.2 Describe how the authentication, authorization and accounting (AAA) security framework is used to manage network access, enforce policies, and monitor user activity
F10: 1.8 | G10: 1.8 Discuss overall education and training and career pathways for workers in the semiconductor industry...
A11: Collaboration | F11: 2.8 | G11: 2.8 Follow cleanroom protocol, housekeeping procedures, and standardized work practices to maintain safety, cleanliness, and product quality (i.e., proper gowning and de-gowning...) | H11: MNT140 | I11: The program prepares students with the foundational expectations for interpersonal and professional skills within the industry. | J11: MSE/ECE 447/ SIE 483 | K11: The processing laboratory provides hands-on semiconductor/MEMS processing experience, which supports coordinated lab work, shared procedures, documentation, and safety/quality practices. Computer-integrated manufacturing links engineering systems and production operations. The Fast Track requires students to complete a team project and present it to industry partners, directly demonstrating collaborative work. | L11: CP-102 | M11: Works productively in diverse teams, sharing responsibilities and coordinating tasks to achieve common project and production goals. | N11: PLTW Engineering (POE, CIM) | O11: Multidisciplinary student teams implement project management frameworks, division of labor (e.g., project manager, lead designer, test technician), peer design reviews, and collaborative technical troubleshooting. | P11: Work in operational teams with engineers, production personnel, and technicians to assemble, test, and refine electronic systems. | Q11: Coordinate with network administrators, vendors, and IT team members to resolve complex system outages and implementation issues. | R11: Collaborate with specialized contractors, building managers, and maintenance teams on facility overhauls and major repairs. | S11: Collaborate with multidisciplinary engineering teams (mechanical, software, systems) to design and integrate automated components.
N12: PLTW Computer Science (SEC)
N13: PLTW Gateway (AR)
A14: Digital Fluency | F14: 7.12 | G14: 7.12 Use basic software tools to view, enter, and understand production or process data (i.e., enter data into a digital log or form... understand basic python scripting, etc.) | H14: AIT132 | I14: The Industrial Technology for Semiconductor certificate includes instruction in “digital fundamentals,” along with AC/DC circuits, solid-state devices, industrial electronics, quality assurance, and semiconductor manufacturing technology. | J14: ECE 407/SIE 483/MSE 480 | K14: ECE 407 addresses digital VLSI system design, aligning with fluency in digital logic/design tools and electronic-system concepts. SIE 483 focuses on computer-integrated manufacturing systems, supporting familiarity with digitally enabled production environments. MSE 480’s emphasis on advanced characterization methods supports interpreting instrument-generated materials data and working with sophisticated technical equipment. | L14: CP-103 | M14: Demonstrates proficiency in navigating digital tools, automated control systems, data entry platforms, and industry-standard software interfaces. | N14: PLTW Engineering (IED, DE, CIM) | O14: Students operate industry-standard software tools (CAD, circuit simulation environments, Python/Java IDEs, G-code software) and physical hardware (3D printers, CNC equipment, microcontrollers, and sensors). | P14: Utilize CAD software, circuit simulation tools (e.g., SPICE), diagnostic software, and computer-based testing interfaces. | Q14: Operate network diagnostic utilities, terminal emulation software, operating system administration tools, and ticketing software. | R14: Utilize Computerized Maintenance Management Systems (CMMS) and digital building automation/HVAC control interfaces. | S14: Apply specialized engineering software (MATLAB, LabVIEW, CAD/CAM), system simulation tools, and embedded system programming environments.
N15: PLTW Computer Science (CSE, CSA, SEC)
F16: 11.1 | G16: 11.1 Distinguish between physical security and cybersecurity (e.g., physical security protects tangible assets like buildings and hardware, and cybersecurity defends digital assets like networks and data) | N16: PLTW Gateway (AC)
A17: Critical Thinking & Problem Solving | F17: 7.1 | G17: 7.1 Read and interpret basic control charts to determine whether a process is operating normally or outside expected limits. | H17: AIT132 | I17: The Industrial Technology for Semiconductor certificate requires students to “apply knowledge of basic semiconductor manufacturing concepts and processes, basic industrial electrical principles, schematics, circuits, hand tools, and appropriate problem-solving models to troubleshoot and address problems in the semiconductor industry.” It also requires students to apply vacuum components, procedures, theory, and tools to “efficiently and effectively troubleshoot common issues found in a system under vacuum.” | J17: MSE/ECE 447/547 | K17: The laboratory course adds applied troubleshooting in semiconductor/MEMS processing. Quality and reliability engineering provide frameworks for analyzing variation, defects, performance, and failure risk. | L17: CP-104 | M17: Analyzes complex process data, identifies root causes of technical anomalies, and implements logical, efficient troubleshooting solutions. | N17: PLTW Engineering (IED, POE, EDD) | O17: Students apply the open-ended PLTW Design Process (Define, Imagine, Design, Create, Test, Evaluate) to diagnose physical/digital system failures, evaluate trade-offs, and iteratively refine designs based on test data. | P17: Critical Thinking — Using logic and reasoning to identify the strengths and weaknesses of alternative solutions, conclusions, or approaches to problems. | Q17: Troubleshooting — Determining causes of operating errors and deciding what to do about them; analyze diagnostic output to resolve network failures. | R17: Inspect, operate, or test machinery to diagnose machine malfunctions; evaluate repair options to determine the most cost-effective solution. | S17: Complex Problem Solving — Identifying complex problems and reviewing related information to develop and evaluate options and implement solutions.
F18: 8.3 | G18: 8.3 Describe basic advantages and limitations of sensors used in manufacturing systems (i.e., size, speed, reliability, need for calibration, drift over time, etc.) | N18: PLTW Biomedical Science (PBS, MI)
F19: 5.12 | G19: 5.12 Troubleshoot piping components and piping systems, pumps, valves, pneumatic and hydraulic components and systems, and heat exchangers | N19: PLTW Gateway (MD)
F20: 2.5 | G20: 2.5 Identify safety procedures when working around automated and robotic systems (i.e., adhere to restricted zones, respond appropriately to alarms...)
F21: 9.5/9.6 | G21: 9.5 / 9.6 Use systematic problem-solving techniques [i.e., root cause and corrective action (RCCA)...] / Explain the basics of standard operating procedures (SOPs)...
A22: Numeracy | F22: 7.4 | G22: 7.4 Apply basic math and unit conversions to support measurements, trends, and simple calculations used in manufacturing environments (i.e., averages, percentages, limits, unit conversions, etc.) | H22: MNT235 | I22: “Covers measurement science, statistical process control, inspection methodologies, measurement system analysis, and failure analysis techniques.” The description also emphasizes “yield optimization, measurement uncertainty, calibration procedures, and implementation of quality control protocols.” | J22: SIE 305/SIE 430 | K22: The minor’s foundational chemistry options include quantitatively oriented coursework. SIE 305 introduces engineering probability and statistics, and SIE 430 builds statistical capability for engineering applications. Together, these courses support measurement, quantitative reasoning, process-data analysis, variation analysis, and evidence-based manufacturing decisions. | L22: CP-105 | M22: Applies mathematical principles, statistical process control, and precise measurement skills to interpret technical specifications and metrics. | N22: PLTW Engineering (POE, DE, IED) | O22: Students calculate force vectors, electrical circuit values (Ohm's/Kirchhoff's Laws), dimensional tolerances using dial calipers, unit conversions, and statistical distribution metrics (mean, standard deviation) from experimental data. | P22: Calculate basic electrical properties (voltage, current, resistance, capacitance) using mathematical formulas, Ohm's law, and algebra. | Q22: Compute network subnet masks, IP address allocations, bandwidth consumption, data transfer rates, and system uptime percentages. | R22: Measure dimensions, calculate surface areas/volumes, compute material quantities, and estimate labor and material costs for maintenance work. | S22: Mathematics — Using mathematics to solve problems; apply advanced principles of calculus, statistics, and linear algebra to system design and yield analysis.
N23: PLTW Biomedical Science (HBS, MI)
N24: PLTW Computer Science (CSA)
A25: Reading & Writing | F25: 11.6/11.7 | G25: 11.6 / 11.7 Identify protocols for cybersecurity threats / Identify protocols for protecting intellectual property | H25: ENG101 | I25: The Semiconductor Manufacturing AAS includes a general-education foundation, and MCCCD identifies Written Communication (WCM) as a course-designation area. ENG101 is the district’s foundational composition course within that requirement structure | J25: CHEE 415 | K25: CHEE 415 adds an applied context for explaining manufacturing-related environmental issues in writing. | L25: CP-106 | M25: Accurately interprets technical manuals, standard operating procedures (SOPs), and schematics while producing clear technical documentation and logs. | N25: PLTW Engineering (All, esp. EDD, IED) | O25: Students maintain legal-grade Engineering Notebooks, conduct academic literature and patent searches, interpret technical specification sheets/schematics, and author formal design proposals and lab reports. | P25: Read and interpret schematics, blueprints, and technical manuals; write test reports, system logs, and standard operating procedures (SOPs). | Q25: Read technical documentation, error logs, and vendor manuals; document network troubleshooting steps, resolution procedures, and user guides. | R25: Read blueprints, building diagrams, electrical schematics, and equipment manuals; maintain written maintenance logs and work orders. | S25: Read technical papers, regulatory compliance standards, and patent specifications; write formal engineering specifications and technical reports.
F26: 2.8 | G26: 2.8 Follow cleanroom protocol... (i.e., documenting issues and near misses, reporting spills, damage, or injuries, etc.) | N26: PLTW Biomedical Science (PBS, BI)
N27: PLTW Computer Science (SEC)
A28: CLUSTER
A29: Interpret basic electrical & circuit concepts & diagrams | B29: Technical Foundations | C29: NA | D29: NA | E29: NA | F29: 6.1-6.4; 7.2 | G29: 6.1-6.4 cover voltage/current/resistance, Ohm's & Kirchhoff's Laws, doping, diodes/transistors/ICs; 7.2 covers schematics and system diagrams. | H29: AIT132 | I29: Program content “includes instruction in AC and DC circuits, digital fundamentals, solid state devices, industrial electronics, and semiconductor manufacturing technology.” | J29: ECE 220 | K29: Covers fundamental AC/DC circuit analysis, Kirchhoff’s laws, operational amplifiers, semiconductor diode/transistor modeling, and reading electrical schematics. | L29: CP-101 / ELC-101 | M29: Analyzes direct and alternating current principles, interprets electrical schematics, reads logic diagrams, and applies Ohm's/Kirchhoff's Laws to circuit diagnostics. | N29: PLTW Engineering (DE, POE) | O29: Students calculate voltage, current, and resistance using Ohm's and Kirchhoff's Laws, design and simulate digital circuit schematics, and construct physical circuits using breadboards and logic components. | P29: Read blueprints, wiring diagrams, schematic drawings, or engineering instructions for assembling electronics units. | Q29: Install or repair network cables, including fiber optic cables. | R29: Plan and lay out repair work, using diagrams, drawings, blueprints, maintenance manuals, or schematic diagrams. | S29: Create schematics and physical layouts of integrated microelectromechanical systems (MEMS); design control circuits.
A30: Use AI and ML tools to optimize manufacturing | B30: Data, Analysis, & Digital Tools | C30: NA | D30: NA | E30: NA | F30: 7.9 | G30: 7.9: “Explain how AI and ML are used in semiconductor manufacturing...to improve manufacturing yields, to improve overall efficiency.” | H30: AIM230 | I30: Explores business and operational integration of AI. Emphasizes leveraging AI/ML tools to streamline supply chains, optimize high-tech factory workflows, reduce operational overhead, and solve industrial scaling challenges. | J30: SIE 574 | K30: Teaches predictive modeling, supervised/unsupervised machine learning, and AI algorithms applied to complex industrial systems and manufacturing optimization. | L30: CP-103 / DAT-110 | M30: Utilizes predictive machine learning algorithms, automated data models, and AI-driven process optimization tools to increase yield and reduce equipment downtime. | N30: PLTW Computer Science (CSE, CSA) | O30: Students utilize Python libraries (e.g., NumPy, Pandas, Scikit-learn) to train machine learning models for predictive analysis, process optimization, and automated decision-making. | P30: Select tools, equipment, or technologies for use in operations or projects; operate computer systems. | Q30: Update knowledge about emerging industry or technology trends; troubleshoot computer systems. | R30: Adjust equipment to ensure optimal performance. | S30: Research, design, develop, or test automation, intelligent systems, smart devices, or industrial systems control.
A31: Use SPC charts and data tools to monitor processes | B31: Data, Analysis, & Digital Tools | C31: NA | D31: NA | E31: NA | F31: 7.1; 9.7 | G31: 7.1 covers reading/interpreting control charts; 9.7: “Explain the basics of Statistical Process Control (SPC) to monitor, control, and improve production processes.” | H31: MNT108 | I31: Focuses directly on the principles and applications of Statistical Process Control (SPC) in semiconductor production. Program learning outcomes specifically require students to "Analyze quality control methods including statistical process control (SPC) through the use of metrology techniques and tools to support quality in semiconductor manufacturing operations." | J31: SIE 540 | K31: Focuses on Statistical Process Control (SPC), control charting (X-bar, R, p-charts), process capability analysis ($C_p$/$C_{pk}$), and design of experiments (DOE) for quality assurance. | L31: CP-103 / GTC-108 | M31: Constructs, reads, and interprets Statistical Process Control (SPC) charts (X-bar, R-charts), monitors trend rules, and uses data software to keep processes within tolerance limits. | N31: PLTW Engineering (IED, CIM) | O31: Students measure manufactured parts, calculate statistical variation (mean, standard deviation, upper/lower control limits), and plot Statistical Process Control (SPC) charts to evaluate manufacturing stability. | P31: Processing Information — Compiling, coding, categorizing, calculating, tabulating, auditing, or verifying information/data. | Q31: Analyze data to identify or resolve operational problems. | R31: Monitoring Processes, Materials, or Surroundings — Monitoring and reviewing information from materials/events to assess problems. | S31: Mathematics/Statistics — Apply math and statistical theory/methods; analyze development or manufacturing procedures.
